Workbook
Name _2月: 资产负债表!$E$5:$E$11
Name Company_Name: 收入!$B$2
Name FiscalYearStartDate: 现金流量表!$B$4
Name Title1: 收入[[#Headers],[收入]]
Name Wksht_Title: 收入!$B$4
Name 标题1: #REF!
Name 标题2: CostofSales[[#Headers],[成本]]
Name 标题3: tblExpenses[[#Headers],[费用]]

Sheet 收支财务报表
A1: 收支财务报表
A3: 序号 | B3: 日期 | C3: 收入 | F3: 支出 | I3: 备注 | K3: =YEAR(TODAY())
C4: 摘要 | D4: 类型 | E4: 金额 | F4: 摘要 | G4: 类型 | H4: 金额
A5: 1 | B5: 46138 | C5: 吴文凯投入 | D5: 贷款/其他现金投入 | E5: 30000 | F5: 米白铝箔底真防潮贴纸60cmx12m | G5: 装修 | H5: 48.28 | I5: https://mobile.yangkeduo.com/goods2.html?ps=pSymVeNXNe | K5: 4
A6: 2 | B6: 46138 | F6: 浅蓝铝箔底真防潮贴纸60cmx12m | G6: 装修 | H6: 48.27 | I6: https://mobile.yangkeduo.com/goods2.html?ps=JwqxaYnoXC | K6: 收入金额
A7: 3 | B7: 46138 | F7: 顶天立地衣架 加高3.6m\加粗38管径5立8横 | G7: 装修 | H7: 380.12 | I7: https://mobile.yangkeduo.com/goods.html?ps=50D9qeUJ2m | K7: {=SUMPRODUCT(($E$5:$E$17200)*(YEAR($B$5:$B$17200)=$K$3)*(MONTH($B$5:$B$17200)=$K$5))}
A8: 4 | B8: 46138 | F8: 小熊板毛毡墙 120*180 | G8: 装修 | H8: 58.1 | I8: https://mobile.yangkeduo.com/goods.html?ps=50D9qeUJ2m | K8: 支出金额
A9: 5 | B9: 46138 | F9: 免打孔安装窗帘杆 白色2.68-3.18m | G9: 装修 | H9: 35.66 | I9: https://mobile.yangkeduo.com/goods.html?ps=CnJSzRfray | K9: =SUMPRODUCT(($H$5:$H$17200)*(YEAR($B$5:$B$17200)=$K$3)*(MONTH($B$5:$B$17200)=$K$5))
A10: 6 | B10: 46138 | F10: 免打孔安装窗帘杆 白色3.18-3.68m | G10: 装修 | H10: 38.93 | I10: https://mobile.yangkeduo.com/goods.html?ps=CnJSzRfray | K10: 结余金额
A11: 7 | B11: 46139 | C11: pq化妆私教课 | D11: 化妆课 | E11: 680 | F11: 萱萱抽成 | G11: 酬劳 | H11: 600 | I11: 工作室成立之前客户 | K11: =K7-K9
A12: 8 | B12: 46144 | F12: 收购工作室服装、道具 | G12: 采购 | H12: 10000 | I12: 萱萱处收购 | K12: 按起止日期查询>>
A13: 9 | B13: 46159 | F13: 神牛 LR500 化妆室灯棒 | G13: 采购 | H13: 860 | I13: 购买化妆室灯棒 Godox LR500；来源：账单截图/IMG_7823.PNG | K13: 开始日期
A14: 10 | B14: 46160 | F14: 工作室化妆品 | G14: 采购 | H14: 696 | I14: 聊天截图注明“工作室化妆品”；来源：账单截图/IMG_7824.PNG | K14: 43831
A15: 11 | K15: 结束日期
K16: =TODAY()
K17: 收入金额
K18: {=SUMPRODUCT(($E$5:$E$17200)*(($B$5:$B$17200)>=$K$14)*(($B$5:$B$17200)<=$K$16))}
K19: 支出金额
K20: =SUMPRODUCT(($H$5:$H$17200)*(($B$5:$B$17200)>=$K$14)*(($B$5:$B$17200)<=$K$16))
K21: 结余金额
K22: =K18-K20

Sheet 现金流量表
B1: 现金流量表
B3: 会计年度起始于: | D3: （预）启动 | E3: =UPPER(TEXT(FiscalYearStartDate,"M 月")) | F3: =UPPER(TEXT(EOMONTH(FiscalYearStartDate,1),"M 月")) | G3: =UPPER(TEXT(EOMONTH(FiscalYearStartDate,2),"M 月")) | H3: =UPPER(TEXT(EOMONTH(FiscalYearStartDate,3),"M 月")) | I3: =UPPER(TEXT(EOMONTH(FiscalYearStartDate,4),"M 月")) | J3: =UPPER(TEXT(EOMONTH(FiscalYearStartDate,5),"M 月")) | K3: =UPPER(TEXT(EOMONTH(FiscalYearStartDate,6),"M 月")) | L3: =UPPER(TEXT(EOMONTH(FiscalYearStartDate,7),"M 月")) | M3: =UPPER(TEXT(EOMONTH(FiscalYearStartDate,8),"M 月")) | N3: =UPPER(TEXT(EOMONTH(FiscalYearStartDate,9),"M 月")) | O3: =UPPER(TEXT(EOMONTH(FiscalYearStartDate,10),"M 月")) | P3: =UPPER(TEXT(EOMONTH(FiscalYearStartDate,11),"M 月")) | R3: 总计
B4: 45658 | D4: EST | E4: =FiscalYearStartDate | F4: =EOMONTH(E4,0)+DAY(FiscalYearStartDate) | G4: =EOMONTH(F4,0)+DAY(FiscalYearStartDate) | H4: =EOMONTH(G4,0)+DAY(FiscalYearStartDate) | I4: =EOMONTH(H4,0)+DAY(FiscalYearStartDate) | J4: =EOMONTH(I4,0)+DAY(FiscalYearStartDate) | K4: =EOMONTH(J4,0)+DAY(FiscalYearStartDate) | L4: =EOMONTH(K4,0)+DAY(FiscalYearStartDate) | M4: =EOMONTH(L4,0)+DAY(FiscalYearStartDate) | ... P4: =EOMONTH(O4,0)+DAY(FiscalYearStartDate) | R4: 项目 EST
B6: 库存现金 (月初) | D6: 0 | E6: =D67 | F6: =E67 | G6: =F67 | H6: =G67 | I6: =H67 | J6: =I67 | K6: =J67 | L6: =K67 | ... P6: =O67 | R6: =P6
B8: 银行卡收入
B9: 薪酬 | R9: =SUM(CashReceipts[[#This Row],[Period 0]:[Period 12]])
B10: 报销 | R10: =SUM(CashReceipts[[#This Row],[Period 0]:[Period 12]])
B11: 贷款/其他现金投入 | H11: 30000 | R11: =SUM(CashReceipts[[#This Row],[Period 0]:[Period 12]])
B12: 资金周转 | R12: =SUM(CashReceipts[[#This Row],[Period 0]:[Period 12]])
B13: 退款 | R13: =SUM(CashReceipts[[#This Row],[Period 0]:[Period 12]])
B14: 投资收益 | R14: =SUM(CashReceipts[[#This Row],[Period 0]:[Period 12]])
B15: 总计 | E15: =SUBTOTAL(109,CashReceipts[Period 1]) | F15: =SUBTOTAL(109,CashReceipts[Period 2]) | G15: =SUBTOTAL(109,CashReceipts[Period 3]) | H15: =SUBTOTAL(109,CashReceipts[Period 4]) | I15: =SUBTOTAL(109,CashReceipts[Period 5]) | J15: =SUBTOTAL(109,CashReceipts[Period 6]) | K15: =SUBTOTAL(109,CashReceipts[Period 7]) | L15: =SUBTOTAL(109,CashReceipts[Period 8]) | M15: =SUBTOTAL(109,CashReceipts[Period 9]) | N15: =SUBTOTAL(109,CashReceipts[Period 10]) | O15: =SUBTOTAL(109,CashReceipts[Period 11]) | P15: =SUBTOTAL(109,CashReceipts[Period 12]) | R15: =SUBTOTAL(109,CashReceipts[Total])
B16: 总可用现金（现金支出前） | D16: =D6+SUM(CashReceipts[Period 0]) | E16: =E6+SUM(CashReceipts[Period 1]) | F16: =F6+SUM(CashReceipts[Period 2]) | G16: =G6+SUM(CashReceipts[Period 3]) | H16: =H6+SUM(CashReceipts[Period 4]) | I16: =I6+SUM(CashReceipts[Period 5]) | J16: =J6+SUM(CashReceipts[Period 6]) | K16: =K6+SUM(CashReceipts[Period 7]) | L16: =L6+SUM(CashReceipts[Period 8]) | M16: =M6+SUM(CashReceipts[Period 9]) | N16: =N6+SUM(CashReceipts[Period 10]) | O16: =O6+SUM(CashReceipts[Period 11]) | P16: =P6+SUM(CashReceipts[Period 12]) | R16: =R6+SUM(CashReceipts[Total])
B18: 投资
B19: 购买基金 | R19: =SUM(CashPaidOut218[[#This Row],[Period 0]:[Period 12]])
B20: 即时高风险投资 | R20: =SUM(CashPaidOut218[[#This Row],[Period 0]:[Period 12]])
B21: 其他启动费用 | R21: =SUM(CashPaidOut218[[#This Row],[Period 0]:[Period 12]])
B22: 保留或由第三人保存 | R22: =SUM(CashPaidOut218[[#This Row],[Period 0]:[Period 12]])
B23: 所有者提款 | R23: =SUM(CashPaidOut218[[#This Row],[Period 0]:[Period 12]])
B24: 总计 | D24: =SUBTOTAL(109,CashPaidOut218[Period 0]) | E24: =SUBTOTAL(109,CashPaidOut218[Period 1]) | F24: =SUBTOTAL(109,CashPaidOut218[Period 2]) | G24: =SUBTOTAL(109,CashPaidOut218[Period 3]) | H24: =SUBTOTAL(109,CashPaidOut218[Period 4]) | I24: =SUBTOTAL(109,CashPaidOut218[Period 5]) | J24: =SUBTOTAL(109,CashPaidOut218[Period 6]) | K24: =SUBTOTAL(109,CashPaidOut218[Period 7]) | L24: =SUBTOTAL(109,CashPaidOut218[Period 8]) | M24: =SUBTOTAL(109,CashPaidOut218[Period 9]) | N24: =SUBTOTAL(109,CashPaidOut218[Period 10]) | O24: =SUBTOTAL(109,CashPaidOut218[Period 11]) | P24: =SUBTOTAL(109,CashPaidOut218[Period 12]) | R24: =SUBTOTAL(109,CashPaidOut218[Total])
B26: 弹性支出
B27: 汽车，运输及差旅费用 | R27: =SUM(CashPaidOut[[#This Row],[Period 0]:[Period 12]])
B28: 信用卡 | R28: =SUM(CashPaidOut[[#This Row],[Period 0]:[Period 12]])
B29: 资金周转 | R29: =SUM(CashPaidOut[[#This Row],[Period 0]:[Period 12]])
B30: 餐饮 | R30: =SUM(CashPaidOut[[#This Row],[Period 0]:[Period 12]])
B31: 红包 | R31: =SUM(CashPaidOut[[#This Row],[Period 0]:[Period 12]])
B32: 购物 | R32: =SUM(CashPaidOut[[#This Row],[Period 0]:[Period 12]])
B33: 服饰美容 | R33: =SUM(CashPaidOut[[#This Row],[Period 0]:[Period 12]])
B34: 文体教育 | R34: =SUM(CashPaidOut[[#This Row],[Period 0]:[Period 12]])
B35: 休闲娱乐 | R35: =SUM(CashPaidOut[[#This Row],[Period 0]:[Period 12]])
B36: 生活用品 | R36: =SUM(CashPaidOut[[#This Row],[Period 0]:[Period 12]])
B37: 宠物 | R37: =SUM(CashPaidOut[[#This Row],[Period 0]:[Period 12]])
B38: 装修 | R38: =SUM(CashPaidOut[[#This Row],[Period 0]:[Period 12]])
... B45: 杂项 | R45: =SUM(CashPaidOut[[#This Row],[Period 0]:[Period 12]])
R46: =SUM(CashPaidOut[[#This Row],[Period 0]:[Period 12]])
R47: =SUM(CashPaidOut[[#This Row],[Period 0]:[Period 12]])
B48: 总计 | D48: =SUBTOTAL(109,CashPaidOut[Period 0]) | E48: =SUBTOTAL(109,CashPaidOut[Period 1]) | F48: =SUBTOTAL(109,CashPaidOut[Period 2]) | G48: =SUBTOTAL(109,CashPaidOut[Period 3]) | H48: =SUBTOTAL(109,CashPaidOut[Period 4]) | I48: =SUBTOTAL(109,CashPaidOut[Period 5]) | J48: =SUBTOTAL(109,CashPaidOut[Period 6]) | K48: =SUBTOTAL(109,CashPaidOut[Period 7]) | L48: =SUBTOTAL(109,CashPaidOut[Period 8]) | M48: =SUBTOTAL(109,CashPaidOut[Period 9]) | N48: =SUBTOTAL(109,CashPaidOut[Period 10]) | O48: =SUBTOTAL(109,CashPaidOut[Period 11]) | P48: =SUBTOTAL(109,CashPaidOut[Period 12]) | R48: =SUBTOTAL(109,CashPaidOut[Total])
B50: 固定支出
B51: 宽带 | R51: =SUM(CashPaidOut2[[#This Row],[Period 0]:[Period 12]])
B52: 电话 | R52: =SUM(CashPaidOut2[[#This Row],[Period 0]:[Period 12]])
...

Sheet 月度预算
B2: 月度预算
B4: 预计月收入 | E4: 预计结余 （预计收入减预计支出） | H4: fgtr6
B5: 收入 1 | C5: 4300
B6: 额外收入 | C6: 300 | E6: 实际余额 （实际收入减实际支出） | H6: =C12-J75
B7: 月总收入 | C7: =SUM(C5:C6)
E8: 差额 （实际值减预计值） | H8: =H6-H4
B9: 实际月收入
B10: 收入 1 | C10: 4000
B11: 额外收入 | C11: 300
B12: 每月总收入 | C12: =SUM(C10:C11)
B14: 住房 | G14: 娱乐
B15: 0 | C15: 预计 费用 | D15: 实际 费用 | E15: 差额 | G15: 0 | H15: 预计 费用 | I15: 实际 费用 | J15: 差额
B16: 抵押贷款或租金 | C16: 1000 | D16: 1000 | E16: =住房[[#This Row],[预计 费用]]-住房[[#This Row],[实际 费用]] | G16: 视频/DVD | J16: =娱乐[[#This Row],[预计 费用]]-娱乐[[#This Row],[实际 费用]]
B17: 电话 | C17: 54 | D17: 100 | E17: =住房[[#This Row],[预计 费用]]-住房[[#This Row],[实际 费用]] | G17: CD | J17: =娱乐[[#This Row],[预计 费用]]-娱乐[[#This Row],[实际 费用]]
B18: 电费 | C18: 44 | D18: 56 | E18: =住房[[#This Row],[预计 费用]]-住房[[#This Row],[实际 费用]] | G18: 电影 | J18: =娱乐[[#This Row],[预计 费用]]-娱乐[[#This Row],[实际 费用]]
B19: 燃气 | C19: 22 | D19: 28 | E19: =住房[[#This Row],[预计 费用]]-住房[[#This Row],[实际 费用]] | G19: 音乐会 | J19: =娱乐[[#This Row],[预计 费用]]-娱乐[[#This Row],[实际 费用]]
B20: 用水和排污 | C20: 8 | D20: 8 | E20: =住房[[#This Row],[预计 费用]]-住房[[#This Row],[实际 费用]] | G20: 体育活动 | J20: =娱乐[[#This Row],[预计 费用]]-娱乐[[#This Row],[实际 费用]]
B21: 有线电视费 | C21: 34 | D21: 34 | E21: =住房[[#This Row],[预计 费用]]-住房[[#This Row],[实际 费用]] | G21: 现场 | J21: =娱乐[[#This Row],[预计 费用]]-娱乐[[#This Row],[实际 费用]]
B22: 垃圾处理 | C22: 10 | D22: 10 | E22: =住房[[#This Row],[预计 费用]]-住房[[#This Row],[实际 费用]] | G22: 其他 | J22: =娱乐[[#This Row],[预计 费用]]-娱乐[[#This Row],[实际 费用]]
B23: 保养或修理 | C23: 23 | D23: 0 | E23: =住房[[#This Row],[预计 费用]]-住房[[#This Row],[实际 费用]] | G23: 其他 | J23: =娱乐[[#This Row],[预计 费用]]-娱乐[[#This Row],[实际 费用]]
B24: 日用品 | C24: 0 | D24: 0 | E24: =住房[[#This Row],[预计 费用]]-住房[[#This Row],[实际 费用]] | G24: 其他 | J24: =娱乐[[#This Row],[预计 费用]]-娱乐[[#This Row],[实际 费用]]
B25: 其他 | C25: 0 | D25: 0 | E25: =住房[[#This Row],[预计 费用]]-住房[[#This Row],[实际 费用]] | G25: 小计 | J25: =SUBTOTAL(109,娱乐[差额])
B26: 小计 | E26: =SUBTOTAL(109,住房[差额])
B28: 交通 | G28: 贷款
B29: 0 | C29: 预计 费用 | D29: 实际 费用 | E29: 差额 | G29: 0 | H29: 预计 费用 | I29: 实际 费用 | J29: 差额
B30: 汽车还款 | E30: =交通[[#This Row],[预计 费用]]-交通[[#This Row],[实际 费用]] | G30: 个人 | J30: =贷款[[#This Row],[预计 费用]]-贷款[[#This Row],[实际 费用]]
B31: 公交/出租车费 | E31: =交通[[#This Row],[预计 费用]]-交通[[#This Row],[实际 费用]] | G31: 学生 | J31: =贷款[[#This Row],[预计 费用]]-贷款[[#This Row],[实际 费用]]
B32: 保险 | E32: =交通[[#This Row],[预计 费用]]-交通[[#This Row],[实际 费用]] | G32: 信用卡 | J32: =贷款[[#This Row],[预计 费用]]-贷款[[#This Row],[实际 费用]]
B33: 牌照 | E33: =交通[[#This Row],[预计 费用]]-交通[[#This Row],[实际 费用]] | G33: 信用卡 | J33: =贷款[[#This Row],[预计 费用]]-贷款[[#This Row],[实际 费用]]
B34: 燃油 | E34: =交通[[#This Row],[预计 费用]]-交通[[#This Row],[实际 费用]] | G34: 信用卡 | J34: =贷款[[#This Row],[预计 费用]]-贷款[[#This Row],[实际 费用]]
B35: 维护 | E35: =交通[[#This Row],[预计 费用]]-交通[[#This Row],[实际 费用]] | G35: 其他 | J35: =贷款[[#This Row],[预计 费用]]-贷款[[#This Row],[实际 费用]]
B36: 其他 | E36: =交通[[#This Row],[预计 费用]]-交通[[#This Row],[实际 费用]] | G36: 小计 | J36: =SUBTOTAL(109,贷款[差额])
B37: 小计 | E37: =SUBTOTAL(109,交通[差额])
B39: 保险 | G39: 税款
B40: 0 | C40: 预计 费用 | D40: 实际 费用 | E40: 差额 | G40: 0 | H40: 预计 费用 | I40: 实际 费用 | J40: 差额
B41: 住宅 | E41: =保险[[#This Row],[预计 费用]]-保险[[#This Row],[实际 费用]] | G41: 国税 | J41: =税款[[#This Row],[预计 费用]]-税款[[#This Row],[实际 费用]]
B42: 健康 | E42: =保险[[#This Row],[预计 费用]]-保险[[#This Row],[实际 费用]] | G42: 省/市/自治区税 | J42: =税款[[#This Row],[预计 费用]]-税款[[#This Row],[实际 费用]]
B43: 人寿 | E43: =保险[[#This Row],[预计 费用]]-保险[[#This Row],[实际 费用]] | G43: 地税 | J43: =税款[[#This Row],[预计 费用]]-税款[[#This Row],[实际 费用]]
B44: 其他 | E44: =保险[[#This Row],[预计 费用]]-保险[[#This Row],[实际 费用]] | G44: 其他 | J44: =税款[[#This Row],[预计 费用]]-税款[[#This Row],[实际 费用]]
B45: 小计 | E45: =SUBTOTAL(109,保险[差额]) | G45: 小计 | J45: =SUBTOTAL(109,税款[差额])
...

Sheet 利润表
C2: 2026化妆工作室
C3: Contoso 利润表
C5: 收入
D7: 销售总额
D8: 减： | E8: 退货和折让
E9: 净销售额 | G9: =F7-F8
C11: 所售商品成本
D13: 期初库存
D14: 加： | E14: 购买
E15: 直接人工费
E16: 间接费用
E17: 可用库存 | G17: =SUM(F13:F17)
D19: 减： | E19: 期末库存
E20: 所售商品成本 | G20: =G17-F19
E22: 总利润（损失） | G22: =G9-G20
C24: 支出
D26: 租金
D27: 分期还款 | F27: 0
D28: 水电费 | F28: 0
D29: 工资和直接成本 | F29: 0
D30: 佣金 | F30: 0
D31: 日用品 | F31: 0
D32: 市场营销 | F32: 0
D33: 物流 | F33: 0
D34: 修理和维护 | F34: 0
D35: 杂项 | F35: 0
D36: 折旧 | F36: 0
D37: 利息 | F37: 0
E38: 费用总计 | G38: =SUM(F26:F38)
E40: 净营业收入 | G40: =G22-G38
C42: 其他收入
D44: 资产销售的收益（损失）
D45: 利息收益
E46: 其他收入总额 | G46: =SUM(F44:F46)
E48: 净收入（损失） | G48: =G40+G46

Sheet 收入
B2: 化妆工作室
B4: 损益预测
B6: 收入 | C6: 趋势 | D6: 1 月 | E6: 2 月 | F6: 3 月 | G6: 4 月 | H6: 5 月 | I6: 6 月 | J6: 7 月 | K6: 8 月 | L6: 9 月 | M6: 10 月 | N6: 11 月 | O6: 12 月 | P6: 年度 | Q6: 行业百分比 | R6: 1 月 % | S6: 2 月 % | T6: 3 月 % | U6: 4 月 % | V6: 5 月 % | W6: 6 月 % | X6: 7 月 % | Y6: 8 月 % | Z6: 9 月 % | AA6: 10 月 % | AB6: 11 月 % | AC6: 12 月 % | AD6: 年度 %
B7: 收入 1 | D7: 186 | E7: 0 | F7: 0 | G7: 0 | H7: 0 | I7: 0 | J7: 0 | K7: 0 | L7: 0 | M7: 0 | N7: 0 | O7: 0 | P7: =SUM(收入[[#This Row],[1 月]:[12 月]]) | Q7: 0.12 | R7: =IFERROR(收入[[#This Row],[1 月]]/收入[[#Totals],[1 月]],"-") | S7: =IFERROR(收入[[#This Row],[2 月]]/收入[[#Totals],[2 月]],"-") | T7: =IFERROR(收入[[#This Row],[3 月]]/收入[[#Totals],[3 月]],"-") | U7: =IFERROR(收入[[#This Row],[4 月]]/收入[[#Totals],[4 月]],"-") | V7: =IFERROR(收入[[#This Row],[5 月]]/收入[[#Totals],[5 月]],"-") | W7: =IFERROR(收入[[#This Row],[6 月]]/收入[[#Totals],[6 月]],"-") | X7: =IFERROR(收入[[#This Row],[7 月]]/收入[[#Totals],[7 月]],"-") | Y7: =IFERROR(收入[[#This Row],[8 月]]/收入[[#Totals],[8 月]],"-") | Z7: =IFERROR(收入[[#This Row],[9 月]]/收入[[#Totals],[9 月]],"-") | AA7: =IFERROR(收入[[#This Row],[10 月]]/收入[[#Totals],[10 月]],"-") | AB7: =IFERROR(收入[[#This Row],[11 月]]/收入[[#Totals],[11 月]],"-") | AC7: =IFERROR(收入[[#This Row],[12 月]]/收入[[#Totals],[12 月]],"-") | AD7: =IFERROR(收入[[#This Row],[年度]]/收入[[#Totals],[年度]],"-")
B8: 收入 2 | D8: 122 | E8: 0 | F8: 0 | G8: 0 | H8: 0 | I8: 0 | J8: 0 | K8: 0 | L8: 0 | M8: 0 | N8: 0 | O8: 0 | P8: =SUM(收入[[#This Row],[1 月]:[12 月]]) | Q8: 0.18 | R8: =IFERROR(收入[[#This Row],[1 月]]/收入[[#Totals],[1 月]],"-") | S8: =IFERROR(收入[[#This Row],[2 月]]/收入[[#Totals],[2 月]],"-") | T8: =IFERROR(收入[[#This Row],[3 月]]/收入[[#Totals],[3 月]],"-") | U8: =IFERROR(收入[[#This Row],[4 月]]/收入[[#Totals],[4 月]],"-") | V8: =IFERROR(收入[[#This Row],[5 月]]/收入[[#Totals],[5 月]],"-") | W8: =IFERROR(收入[[#This Row],[6 月]]/收入[[#Totals],[6 月]],"-") | X8: =IFERROR(收入[[#This Row],[7 月]]/收入[[#Totals],[7 月]],"-") | Y8: =IFERROR(收入[[#This Row],[8 月]]/收入[[#Totals],[8 月]],"-") | Z8: =IFERROR(收入[[#This Row],[9 月]]/收入[[#Totals],[9 月]],"-") | AA8: =IFERROR(收入[[#This Row],[10 月]]/收入[[#Totals],[10 月]],"-") | AB8: =IFERROR(收入[[#This Row],[11 月]]/收入[[#Totals],[11 月]],"-") | AC8: =IFERROR(收入[[#This Row],[12 月]]/收入[[#Totals],[12 月]],"-") | AD8: =IFERROR(收入[[#This Row],[年度]]/收入[[#Totals],[年度]],"-")
B9: 收入 3 | D9: 166 | E9: 0 | F9: 0 | G9: 0 | H9: 0 | I9: 0 | J9: 0 | K9: 0 | L9: 0 | M9: 0 | N9: 0 | O9: 0 | P9: =SUM(收入[[#This Row],[1 月]:[12 月]]) | Q9: 0.19 | R9: =IFERROR(收入[[#This Row],[1 月]]/收入[[#Totals],[1 月]],"-") | S9: =IFERROR(收入[[#This Row],[2 月]]/收入[[#Totals],[2 月]],"-") | T9: =IFERROR(收入[[#This Row],[3 月]]/收入[[#Totals],[3 月]],"-") | U9: =IFERROR(收入[[#This Row],[4 月]]/收入[[#Totals],[4 月]],"-") | V9: =IFERROR(收入[[#This Row],[5 月]]/收入[[#Totals],[5 月]],"-") | W9: =IFERROR(收入[[#This Row],[6 月]]/收入[[#Totals],[6 月]],"-") | X9: =IFERROR(收入[[#This Row],[7 月]]/收入[[#Totals],[7 月]],"-") | Y9: =IFERROR(收入[[#This Row],[8 月]]/收入[[#Totals],[8 月]],"-") | Z9: =IFERROR(收入[[#This Row],[9 月]]/收入[[#Totals],[9 月]],"-") | AA9: =IFERROR(收入[[#This Row],[10 月]]/收入[[#Totals],[10 月]],"-") | AB9: =IFERROR(收入[[#This Row],[11 月]]/收入[[#Totals],[11 月]],"-") | AC9: =IFERROR(收入[[#This Row],[12 月]]/收入[[#Totals],[12 月]],"-") | AD9: =IFERROR(收入[[#This Row],[年度]]/收入[[#Totals],[年度]],"-")
B10: 收入 4 | D10: 21 | E10: 0 | F10: 0 | G10: 0 | H10: 0 | I10: 0 | J10: 0 | K10: 0 | L10: 0 | M10: 0 | N10: 0 | O10: 0 | P10: =SUM(收入[[#This Row],[1 月]:[12 月]]) | Q10: 0.11 | R10: =IFERROR(收入[[#This Row],[1 月]]/收入[[#Totals],[1 月]],"-") | S10: =IFERROR(收入[[#This Row],[2 月]]/收入[[#Totals],[2 月]],"-") | T10: =IFERROR(收入[[#This Row],[3 月]]/收入[[#Totals],[3 月]],"-") | U10: =IFERROR(收入[[#This Row],[4 月]]/收入[[#Totals],[4 月]],"-") | V10: =IFERROR(收入[[#This Row],[5 月]]/收入[[#Totals],[5 月]],"-") | W10: =IFERROR(收入[[#This Row],[6 月]]/收入[[#Totals],[6 月]],"-") | X10: =IFERROR(收入[[#This Row],[7 月]]/收入[[#Totals],[7 月]],"-") | Y10: =IFERROR(收入[[#This Row],[8 月]]/收入[[#Totals],[8 月]],"-") | Z10: =IFERROR(收入[[#This Row],[9 月]]/收入[[#Totals],[9 月]],"-") | AA10: =IFERROR(收入[[#This Row],[10 月]]/收入[[#Totals],[10 月]],"-") | AB10: =IFERROR(收入[[#This Row],[11 月]]/收入[[#Totals],[11 月]],"-") | AC10: =IFERROR(收入[[#This Row],[12 月]]/收入[[#Totals],[12 月]],"-") | AD10: =IFERROR(收入[[#This Row],[年度]]/收入[[#Totals],[年度]],"-")
B11: 收入 5 | D11: 70 | E11: 0 | F11: 0 | G11: 0 | H11: 0 | I11: 0 | J11: 0 | K11: 0 | L11: 0 | M11: 0 | N11: 0 | O11: 0 | P11: =SUM(收入[[#This Row],[1 月]:[12 月]]) | Q11: 0.2 | R11: =IFERROR(收入[[#This Row],[1 月]]/收入[[#Totals],[1 月]],"-") | S11: =IFERROR(收入[[#This Row],[2 月]]/收入[[#Totals],[2 月]],"-") | T11: =IFERROR(收入[[#This Row],[3 月]]/收入[[#Totals],[3 月]],"-") | U11: =IFERROR(收入[[#This Row],[4 月]]/收入[[#Totals],[4 月]],"-") | V11: =IFERROR(收入[[#This Row],[5 月]]/收入[[#Totals],[5 月]],"-") | W11: =IFERROR(收入[[#This Row],[6 月]]/收入[[#Totals],[6 月]],"-") | X11: =IFERROR(收入[[#This Row],[7 月]]/收入[[#Totals],[7 月]],"-") | Y11: =IFERROR(收入[[#This Row],[8 月]]/收入[[#Totals],[8 月]],"-") | Z11: =IFERROR(收入[[#This Row],[9 月]]/收入[[#Totals],[9 月]],"-") | AA11: =IFERROR(收入[[#This Row],[10 月]]/收入[[#Totals],[10 月]],"-") | AB11: =IFERROR(收入[[#This Row],[11 月]]/收入[[#Totals],[11 月]],"-") | AC11: =IFERROR(收入[[#This Row],[12 月]]/收入[[#Totals],[12 月]],"-") | AD11: =IFERROR(收入[[#This Row],[年度]]/收入[[#Totals],[年度]],"-")
B12: 收入 6 | D12: 61 | E12: 0 | F12: 0 | G12: 0 | H12: 0 | I12: 0 | J12: 0 | K12: 0 | L12: 0 | M12: 0 | N12: 0 | O12: 0 | P12: =SUM(收入[[#This Row],[1 月]:[12 月]]) | Q12: 0.1 | R12: =IFERROR(收入[[#This Row],[1 月]]/收入[[#Totals],[1 月]],"-") | S12: =IFERROR(收入[[#This Row],[2 月]]/收入[[#Totals],[2 月]],"-") | T12: =IFERROR(收入[[#This Row],[3 月]]/收入[[#Totals],[3 月]],"-") | U12: =IFERROR(收入[[#This Row],[4 月]]/收入[[#Totals],[4 月]],"-") | V12: =IFERROR(收入[[#This Row],[5 月]]/收入[[#Totals],[5 月]],"-") | W12: =IFERROR(收入[[#This Row],[6 月]]/收入[[#Totals],[6 月]],"-") | X12: =IFERROR(收入[[#This Row],[7 月]]/收入[[#Totals],[7 月]],"-") | Y12: =IFERROR(收入[[#This Row],[8 月]]/收入[[#Totals],[8 月]],"-") | Z12: =IFERROR(收入[[#This Row],[9 月]]/收入[[#Totals],[9 月]],"-") | AA12: =IFERROR(收入[[#This Row],[10 月]]/收入[[#Totals],[10 月]],"-") | AB12: =IFERROR(收入[[#This Row],[11 月]]/收入[[#Totals],[11 月]],"-") | AC12: =IFERROR(收入[[#This Row],[12 月]]/收入[[#Totals],[12 月]],"-") | AD12: =IFERROR(收入[[#This Row],[年度]]/收入[[#Totals],[年度]],"-")
B13: 收入 7 | D13: 105 | E13: 0 | F13: 0 | G13: 0 | H13: 0 | I13: 0 | J13: 0 | K13: 0 | L13: 0 | M13: 0 | N13: 0 | O13: 0 | P13: =SUM(收入[[#This Row],[1 月]:[12 月]]) | Q13: 0.1 | R13: =IFERROR(收入[[#This Row],[1 月]]/收入[[#Totals],[1 月]],"-") | S13: =IFERROR(收入[[#This Row],[2 月]]/收入[[#Totals],[2 月]],"-") | T13: =IFERROR(收入[[#This Row],[3 月]]/收入[[#Totals],[3 月]],"-") | U13: =IFERROR(收入[[#This Row],[4 月]]/收入[[#Totals],[4 月]],"-") | V13: =IFERROR(收入[[#This Row],[5 月]]/收入[[#Totals],[5 月]],"-") | W13: =IFERROR(收入[[#This Row],[6 月]]/收入[[#Totals],[6 月]],"-") | X13: =IFERROR(收入[[#This Row],[7 月]]/收入[[#Totals],[7 月]],"-") | Y13: =IFERROR(收入[[#This Row],[8 月]]/收入[[#Totals],[8 月]],"-") | Z13: =IFERROR(收入[[#This Row],[9 月]]/收入[[#Totals],[9 月]],"-") | AA13: =IFERROR(收入[[#This Row],[10 月]]/收入[[#Totals],[10 月]],"-") | AB13: =IFERROR(收入[[#This Row],[11 月]]/收入[[#Totals],[11 月]],"-") | AC13: =IFERROR(收入[[#This Row],[12 月]]/收入[[#Totals],[12 月]],"-") | AD13: =IFERROR(收入[[#This Row],[年度]]/收入[[#Totals],[年度]],"-")
B14: 总销售额 | D14: =SUBTOTAL(109,收入[1 月]) | E14: =SUBTOTAL(109,收入[2 月]) | F14: =SUBTOTAL(109,收入[3 月]) | G14: =SUBTOTAL(109,收入[4 月]) | H14: =SUBTOTAL(109,收入[5 月]) | I14: =SUBTOTAL(109,收入[6 月]) | J14: =SUBTOTAL(109,收入[7 月]) | K14: =SUBTOTAL(109,收入[8 月]) | L14: =SUBTOTAL(109,收入[9 月]) | M14: =SUBTOTAL(109,收入[10 月]) | N14: =SUBTOTAL(109,收入[11 月]) | O14: =SUBTOTAL(109,收入[12 月]) | P14: =SUBTOTAL(109,收入[年度]) | Q14: =SUBTOTAL(109,收入[行业百分比]) | R14: =SUBTOTAL(109,收入[1 月 %]) | S14: =SUBTOTAL(109,收入[2 月 %]) | T14: =SUBTOTAL(109,收入[3 月 %]) | U14: =SUBTOTAL(109,收入[4 月 %]) | V14: =SUBTOTAL(109,收入[5 月 %]) | W14: =SUBTOTAL(109,收入[6 月 %]) | X14: =SUBTOTAL(109,收入[7 月 %]) | Y14: =SUBTOTAL(109,收入[8 月 %]) | Z14: =SUBTOTAL(109,收入[9 月 %]) | AA14: =SUBTOTAL(109,收入[10 月 %]) | AB14: =SUBTOTAL(109,收入[11 月 %]) | AC14: =SUBTOTAL(109,收入[12 月 %]) | AD14: =SUBTOTAL(109,收入[年度 %])

Sheet 成本
B2: =Company_Name
B4: =Wksht_Title
B6: 成本 | C6: 趋势 | D6: 1 月 | E6: 2 月 | F6: 3 月 | G6: 4 月 | H6: 5 月 | I6: 6 月 | J6: 7 月 | K6: 8 月 | L6: 9 月 | M6: 10 月 | N6: 11 月 | O6: 12 月 | P6: 年度 | Q6: 指数 % | R6: 1 月 % | S6: 2 月 % | T6: 3 月 % | U6: 4 月 % | V6: 5 月 % | W6: 6 月 % | X6: 7 月 % | Y6: 8 月 % | Z6: 9 月 % | AA6: 10 月 % | AB6: 11 月 % | AC6: 12 月 % | AD6: 年度 %
B7: 购买费用 | D7: 61 | E7: 0 | F7: 0 | G7: 620.6 | H7: 13955.73 | I7: 0 | J7: 0 | K7: 0 | L7: 0 | M7: 0 | N7: 0 | O7: 0 | P7: =SUM(CostofSales[[#This Row],[1 月]:[12 月]]) | Q7: 0.12 | R7: =D7/D$14 | S7: =E7/E$14 | T7: =F7/F$14 | U7: =G7/G$14 | V7: =H7/H$14 | W7: =I7/I$14 | X7: =J7/J$14 | Y7: =K7/K$14 | ... AD7: =P7/P$14
B8: 直接人工费 | D8: 7 | E8: 0 | F8: 0 | G8: 0 | H8: 0 | I8: 0 | J8: 0 | K8: 0 | L8: 0 | M8: 0 | N8: 0 | O8: 0 | P8: =SUM(CostofSales[[#This Row],[1 月]:[12 月]]) | Q8: 0.18 | R8: =D8/D$14 | S8: =E8/E$14 | T8: =F8/F$14 | U8: =G8/G$14 | V8: =H8/H$14 | W8: =I8/I$14 | X8: =J8/J$14 | Y8: =K8/K$14 | ... AD8: =P8/P$14
B9: 间接费用 | D9: 99 | E9: 0 | F9: 0 | G9: 0 | H9: 0 | I9: 0 | J9: 0 | K9: 0 | L9: 0 | M9: 0 | N9: 0 | O9: 0 | P9: =SUM(CostofSales[[#This Row],[1 月]:[12 月]]) | Q9: 0.19 | R9: =D9/D$14 | S9: =E9/E$14 | T9: =F9/F$14 | U9: =G9/G$14 | V9: =H9/H$14 | W9: =I9/I$14 | X9: =J9/J$14 | Y9: =K9/K$14 | ... AD9: =P9/P$14
B10: 退货 | D10: 13 | E10: 0 | F10: 0 | G10: 0 | H10: 0 | I10: 0 | J10: 0 | K10: 0 | L10: 0 | M10: 0 | N10: 0 | O10: 0 | P10: =SUM(CostofSales[[#This Row],[1 月]:[12 月]]) | Q10: 0.11 | R10: =D10/D$14 | S10: =E10/E$14 | T10: =F10/F$14 | U10: =G10/G$14 | V10: =H10/H$14 | W10: =I10/I$14 | X10: =J10/J$14 | Y10: =K10/K$14 | ... AD10: =P10/P$14
B11: 初期库存 | D11: 34 | E11: 0 | F11: 0 | G11: 0 | H11: 0 | I11: 0 | J11: 0 | K11: 0 | L11: 0 | M11: 0 | N11: 0 | O11: 0 | P11: =SUM(CostofSales[[#This Row],[1 月]:[12 月]]) | Q11: 0.2 | R11: =D11/D$14 | S11: =E11/E$14 | T11: =F11/F$14 | U11: =G11/G$14 | V11: =H11/H$14 | W11: =I11/I$14 | X11: =J11/J$14 | Y11: =K11/K$14 | ... AD11: =P11/P$14
B12: 期末库存 | D12: 33 | E12: 0 | F12: 0 | G12: 0 | H12: 0 | I12: 0 | J12: 0 | K12: 0 | L12: 0 | M12: 0 | N12: 0 | O12: 0 | P12: =SUM(CostofSales[[#This Row],[1 月]:[12 月]]) | Q12: 0.1 | R12: =D12/D$14 | S12: =E12/E$14 | T12: =F12/F$14 | U12: =G12/G$14 | V12: =H12/H$14 | W12: =I12/I$14 | X12: =J12/J$14 | Y12: =K12/K$14 | ... AD12: =P12/P$14
B13: 所售商品成本 | D13: 18 | E13: 0 | F13: 0 | G13: 0 | H13: 0 | I13: 0 | J13: 0 | K13: 0 | L13: 0 | M13: 0 | N13: 0 | O13: 0 | P13: =SUM(CostofSales[[#This Row],[1 月]:[12 月]]) | Q13: 0.1 | R13: =D13/D$14 | S13: =E13/E$14 | T13: =F13/F$14 | U13: =G13/G$14 | V13: =H13/H$14 | W13: =I13/I$14 | X13: =J13/J$14 | Y13: =K13/K$14 | ... AD13: =P13/P$14
B14: 销售总成本 | D14: =SUM(D7:D10,D13) | E14: =SUM(E7:E10,E13) | F14: =SUM(F7:F10,F13) | G14: =SUM(G7:G10,G13) | H14: =SUM(H7:H10,H13) | I14: =SUM(I7:I10,I13) | J14: =SUM(J7:J10,J13) | K14: =SUM(K7:K10,K13) | ... O14: =SUM(O7:O10,O13) | P14: =SUM(CostofSales[[#This Row],[1 月]:[12 月]]) | Q14: =SUM(Q7:Q13) | R14: =D14/D$14 | S14: =E14/E$14 | T14: =F14/F$14 | U14: =G14/G$14 | V14: =H14/H$14 | W14: =I14/I$14 | X14: =J14/J$14 | Y14: =K14/K$14 | ... AD14: =P14/P$14
B15: 毛利润 | D15: =收入!D14-D14 | E15: =收入!E14-E14 | F15: =收入!F14-F14 | G15: =收入!G14-G14 | H15: =收入!H14-H14 | I15: =收入!I14-I14 | J15: =收入!J14-J14 | K15: =收入!K14-K14 | ... P15: =收入!P14-P14

Sheet 支出
B2: =Company_Name
B4: =Wksht_Title
B6: 费用 | C6: 趋势 | D6: 1 月 | E6: 2 月 | F6: 3 月 | G6: 4 月 | H6: 5 月 | I6: 6 月 | J6: 7 月 | K6: 8 月 | L6: 9 月 | M6: 10 月 | N6: 11 月 | O6: 12 月 | P6: 年度 | Q6: 指数 % | R6: 1 月 % | S6: 2 月 % | T6: 3 月 % | U6: 4 月 % | V6: 5 月 % | W6: 6 月 % | X6: 7 月 % | Y6: 8 月 % | Z6: 9 月 % | AA6: 10 月 % | AB6: 11 月 % | AC6: 12 月 % | AD6: 年度 %
B7: 工资支出 | D7: 10 | E7: 18 | F7: 13 | G7: 8 | H7: 22 | I7: 18 | J7: 8 | K7: 17 | L7: 20 | M7: 8 | N7: 4 | O7: 12 | P7: =SUM(tblExpenses[[#This Row],[1 月]:[12 月]]) | Q7: 0.12 | R7: =D7/D$26 | S7: =E7/E$26 | T7: =F7/F$26 | U7: =G7/G$26 | V7: =H7/H$26 | W7: =I7/I$26 | X7: =J7/J$26 | Y7: =K7/K$26 | ... AD7: =P7/P$26
B8: 薪金支出 | D8: 23 | E8: 11 | F8: 7 | G8: 14 | H8: 12 | I8: 19 | J8: 19 | K8: 4 | L8: 7 | M8: 13 | N8: 25 | O8: 5 | P8: =SUM(tblExpenses[[#This Row],[1 月]:[12 月]]) | Q8: 0.09 | R8: =D8/D$26 | S8: =E8/E$26 | T8: =F8/F$26 | U8: =G8/G$26 | V8: =H8/H$26 | W8: =I8/I$26 | X8: =J8/J$26 | Y8: =K8/K$26 | ... AD8: =P8/P$26
B9: 外部服务 | D9: 23 | E9: 20 | F9: 3 | G9: 716 | H9: 13 | I9: 5 | J9: 20 | K9: 7 | L9: 4 | M9: 22 | N9: 13 | O9: 14 | P9: =SUM(tblExpenses[[#This Row],[1 月]:[12 月]]) | Q9: 0.02 | R9: =D9/D$26 | S9: =E9/E$26 | T9: =F9/F$26 | U9: =G9/G$26 | V9: =H9/H$26 | W9: =I9/I$26 | X9: =J9/J$26 | Y9: =K9/K$26 | ... AD9: =P9/P$26
B10: 补给（办公室和运营） | D10: 19 | E10: 4 | F10: 7 | G10: 14 | H10: 388 | I10: 10 | J10: 22 | K10: 5 | L10: 4 | M10: 12 | N10: 18 | O10: 24 | P10: =SUM(tblExpenses[[#This Row],[1 月]:[12 月]]) | Q10: 0.08 | R10: =D10/D$26 | S10: =E10/E$26 | T10: =F10/F$26 | U10: =G10/G$26 | V10: =H10/H$26 | W10: =I10/I$26 | X10: =J10/J$26 | Y10: =K10/K$26 | ... AD10: =P10/P$26
B11: 修理和维护 | D11: 11 | E11: 11 | F11: 17 | G11: 12 | H11: 2 | I11: 14 | J11: 12 | K11: 10 | L11: 18 | M11: 11 | N11: 23 | O11: 11 | P11: =SUM(tblExpenses[[#This Row],[1 月]:[12 月]]) | Q11: 0.03 | R11: =D11/D$26 | S11: =E11/E$26 | T11: =F11/F$26 | U11: =G11/G$26 | V11: =H11/H$26 | W11: =I11/I$26 | X11: =J11/J$26 | Y11: =K11/K$26 | ... AD11: =P11/P$26
B12: 广告 | D12: 2 | E12: 16 | F12: 6 | G12: 13 | H12: 11 | I12: 22 | J12: 21 | K12: 3 | L12: 12 | M12: 7 | N12: 17 | O12: 20 | P12: =SUM(tblExpenses[[#This Row],[1 月]:[12 月]]) | Q12: 0.15 | R12: =D12/D$26 | S12: =E12/E$26 | T12: =F12/F$26 | U12: =G12/G$26 | V12: =H12/H$26 | W12: =I12/I$26 | X12: =J12/J$26 | Y12: =K12/K$26 | ... AD12: =P12/P$26
B13: 汽车、送货和旅行 | D13: 8 | E13: 17 | F13: 11 | G13: 11 | H13: 21 | I13: 9 | J13: 20 | K13: 3 | L13: 14 | M13: 22 | N13: 16 | O13: 12 | P13: =SUM(tblExpenses[[#This Row],[1 月]:[12 月]]) | Q13: 0.12 | R13: =D13/D$26 | S13: =E13/E$26 | T13: =F13/F$26 | U13: =G13/G$26 | V13: =H13/H$26 | W13: =I13/I$26 | X13: =J13/J$26 | Y13: =K13/K$26 | ... AD13: =P13/P$26
B14: 会计和法律 | D14: 5 | E14: 13 | F14: 6 | G14: 15 | H14: 19 | I14: 10 | J14: 12 | K14: 9 | L14: 15 | M14: 16 | N14: 4 | O14: 9 | P14: =SUM(tblExpenses[[#This Row],[1 月]:[12 月]]) | Q14: 0.09 | R14: =D14/D$26 | S14: =E14/E$26 | T14: =F14/F$26 | U14: =G14/G$26 | V14: =H14/H$26 | W14: =I14/I$26 | X14: =J14/J$26 | Y14: =K14/K$26 | ... AD14: =P14/P$26
B15: 租金 | D15: 8 | E15: 4 | F15: 23 | G15: 25 | H15: 10 | I15: 24 | J15: 22 | K15: 5 | L15: 12 | M15: 24 | N15: 24 | O15: 12 | P15: =SUM(tblExpenses[[#This Row],[1 月]:[12 月]]) | Q15: 0.01 | R15: =D15/D$26 | S15: =E15/E$26 | T15: =F15/F$26 | U15: =G15/G$26 | V15: =H15/H$26 | W15: =I15/I$26 | X15: =J15/J$26 | Y15: =K15/K$26 | ... AD15: =P15/P$26
B16: 电话 | D16: 25 | E16: 2 | F16: 12 | G16: 25 | H16: 10 | I16: 24 | J16: 3 | K16: 20 | L16: 3 | M16: 9 | N16: 20 | O16: 18 | P16: =SUM(tblExpenses[[#This Row],[1 月]:[12 月]]) | Q16: 0.01 | R16: =D16/D$26 | S16: =E16/E$26 | T16: =F16/F$26 | U16: =G16/G$26 | V16: =H16/H$26 | W16: =I16/I$26 | X16: =J16/J$26 | Y16: =K16/K$26 | ... AD16: =P16/P$26
B17: 水电费 | D17: 16 | E17: 19 | F17: 9 | G17: 16 | H17: 13 | I17: 2 | J17: 4 | K17: 24 | L17: 16 | M17: 22 | N17: 7 | O17: 18 | P17: =SUM(tblExpenses[[#This Row],[1 月]:[12 月]]) | Q17: 0.01 | R17: =D17/D$26 | S17: =E17/E$26 | T17: =F17/F$26 | U17: =G17/G$26 | V17: =H17/H$26 | W17: =I17/I$26 | X17: =J17/J$26 | Y17: =K17/K$26 | ... AD17: =P17/P$26
B18: 保险 | D18: 12 | E18: 9 | F18: 16 | G18: 19 | H18: 25 | I18: 17 | J18: 20 | K18: 14 | L18: 5 | M18: 14 | N18: 5 | O18: 2 | P18: =SUM(tblExpenses[[#This Row],[1 月]:[12 月]]) | Q18: 0.01 | R18: =D18/D$26 | S18: =E18/E$26 | T18: =F18/F$26 | U18: =G18/G$26 | V18: =H18/H$26 | W18: =I18/I$26 | X18: =J18/J$26 | Y18: =K18/K$26 | ... AD18: =P18/P$26
... B25: 杂项（未指定） | D25: 8 | E25: 20 | F25: 11 | G25: 11 | H25: 11 | I25: 20 | J25: 12 | K25: 16 | L25: 5 | M25: 7 | N25: 21 | O25: 3 | P25: =SUM(tblExpenses[[#This Row],[1 月]:[12 月]]) | Q25: 0.02 | R25: =D25/D$26 | S25: =E25/E$26 | T25: =F25/F$26 | U25: =G25/G$26 | V25: =H25/H$26 | W25: =I25/I$26 | X25: =J25/J$26 | Y25: =K25/K$26 | ... AD25: =P25/P$26
B26: 费用总计 | D26: =SUM(D7:D25) | E26: =SUM(E7:E25) | F26: =SUM(F7:F25) | G26: =SUM(G7:G25) | H26: =SUM(H7:H25) | I26: =SUM(I7:I25) | J26: =SUM(J7:J25) | K26: =SUM(K7:K25) | ... O26: =SUM(O7:O25) | P26: =SUM(tblExpenses[[#This Row],[1 月]:[12 月]]) | Q26: =SUM(Q7:Q25) | R26: =D26/D$26 | S26: =E26/E$26 | T26: =F26/F$26 | U26: =G26/G$26 | V26: =H26/H$26 | W26: =I26/I$26 | X26: =J26/J$26 | Y26: =K26/K$26 | ... AD26: =P26/P$26
B27: 净利润 | D27: =成本!D15-D26 | E27: =成本!E15-E26 | F27: =成本!F15-F26 | G27: =成本!G15-G26 | H27: =成本!H15-H26 | I27: =成本!I15-I26 | J27: =成本!J15-J26 | K27: =成本!K15-K26 | ... P27: =成本!P15-P26

Sheet 固定资产记录
B2: 包含双倍递减折旧计算的固定资产记录
B3: 资产名称 | C3: 资产类别 | D3: 描述 | E3: 图片 | F3: 成片 | G3: 序列号 | H3: 购进日期 | I3: 购进价格 | J3: 估计使用寿命（年） | K3: 估计折旧残值 | L3: 折旧年限 | M3: 估计双倍递减折旧值
B4: 香染衣罗原创【隆客吟】紫色印花衫子三裥裙蓝色齐胸裙汉服套装 | C4: 汉服 | D4: 天水葡萄酒厂行政办公楼 | F4: 2 | G4: 无 | H4: 43990 | I4: 480000 | J4: 20 | K4: 100000 | L4: 2 | M4: =IF(AND(I4<>0,K4<>0,J4<>0,L4<>0),DDB(I4,K4,J4,L4),"")
B5: 行政办公楼服务器 | C5: 机械和设备 | D5: 用于存储公司文件的服务器 | E5: 行政办公楼 4 层 | F5: 14 | G5: 4463-22A | H5: 38146 | I5: 124000 | J5: 5 | K5: 20000 | L5: 2 | M5: =IF(AND(I5<>0,K5<>0,J5<>0,L5<>0),DDB(I5,K5,J5,L5),"")
M6: =IF(AND(I6<>0,K6<>0,J6<>0,L6<>0),DDB(I6,K6,J6,L6),"")
M7: =IF(AND(I7<>0,K7<>0,J7<>0,L7<>0),DDB(I7,K7,J7,L7),"")
B10: 包含固定递减折旧计算的固定资产记录
B11: 资产名称 | C11: 资产类别 | D11: 描述 | E11: 物理位置 | F11: 资产编号 | G11: 序列号 | H11: 购进日期 | I11: 购进价格 | J11: 估计使用寿命（年） | K11: 估计折旧残值 | L11: 折旧年限 | M11: 估计固定递减折旧值
B12: 行政办公楼 | C12: 建筑物 | D12: 天水葡萄酒厂行政办公楼 | E12: 幸福大街 123 号 | F12: 2 | G12: 无 | H12: 37661 | I12: 480000 | J12: 20 | K12: 100000 | L12: 2 | M12: =IF(AND(I12<>0,K12<>0,J12<>0,L12<>0),DB(I12,K12,J12,L12),"")
B13: 行政办公楼服务器 | C13: 机械和设备 | D13: 用于存储公司文件的服务器 | E13: 行政办公楼 4 层 | F13: 14 | G13: 4463-22A | H13: 38146 | I13: 124000 | J13: 5 | K13: 20000 | L13: 2 | M13: =IF(AND(I13<>0,K13<>0,J13<>0,L13<>0),DB(I13,K13,J13,L13),"")
M14: =IF(AND(I14<>0,K14<>0,J14<>0,L14<>0),DB(I14,K14,J14,L14),"")
B16: 包含直线折旧计算的固定资产记录
B17: 资产名称 | C17: 资产类别 | D17: 描述 | E17: 物理位置 | F17: 资产编号 | G17: 序列号 | H17: 购进日期 | I17: 购进价格 | J17: 估计使用寿命（年） | K17: 估计折旧残值 | L17: 估计直线折旧值
B18: 行政办公楼 | C18: 建筑物 | D18: 天水葡萄酒厂行政办公楼 | E18: 幸福大街 123 号 | F18: 2 | G18: 无 | H18: 36931 | I18: 480000 | J18: 20 | K18: 100000 | L18: =IF(AND(I18<>0,K18<>0,J18<>0),SLN(I18,K18,J18),"")
B19: 行政办公楼服务器 | C19: 机械和设备 | D19: 用于存储公司文件的服务器 | E19: 行政办公楼 4 层 | F19: 14 | G19: 4463-22A | H19: 38146 | I19: 124000 | J19: 5 | K19: 20000 | L19: =IF(AND(I19<>0,K19<>0,J19<>0),SLN(I19,K19,J19),"")
L20: =IF(AND(I20<>0,K20<>0,J20<>0),SLN(I20,K20,J20),"")

Sheet 资产负债表
A1: 在此工作表中创建资产负债表。此列的单元格中显示有关如何使用此工作表的有用说明。向下移动箭头以开始了解。 | B1: 2025 | O1: 资产负责表
A2: 在右侧单元格中输入公司名称。此工作表的标题位于单元格 D1 中。下一条指示位于单元格 A4 中。
A4: 资产标签位于右侧单元格中。 | B4: 资产
A5: 从右侧单元格开始，在“流动资产”表格中输入详细信息。下一条说明位于单元格 A14 中。 | B5: 流动资产： | C5: 上一年度 | D5: 1月 | E5: 2月 | F5: 3月 | G5: 4月 | H5: 5月 | I5: 6月 | J5: 7月 | K5: 8月 | L5: 9月 | M5: 10月 | N5: 11月 | O5: 12月
B6: 现金 | C6: =现金流量表!D67 | D6: 0 | E6: 0 | F6: 0 | G6: 0 | H6: 0 | I6: 0 | J6: 0 | K6: 0 | L6: 0 | M6: 0 | N6: 0 | O6: 0
B7: 投资 | C7: 0 | D7: 0 | E7: 0 | F7: 0 | G7: 0 | H7: 0 | I7: 0 | J7: 0 | K7: 0 | L7: 0 | M7: 0 | N7: 0 | O7: 0
B8: 库存 | C8: 0 | D8: 0 | E8: 0 | F8: 0 | G8: 0 | H8: 0 | I8: 0 | J8: 0 | K8: 0 | L8: 0 | M8: 0 | N8: 0 | O8: 0
B9: 应收帐款 | C9: 0 | D9: 0 | E9: 0 | F9: 0 | G9: 0 | H9: 0 | I9: 0 | J9: 0 | K9: 0 | L9: 0 | M9: 0 | N9: 0 | O9: 0
B10: 预付费用 | C10: 0 | D10: 0 | E10: 0 | F10: 0 | G10: 0 | H10: 0 | I10: 0 | J10: 0 | K10: 0 | L10: 0 | M10: 0 | N10: 0 | O10: 0
B11: 其他 | C11: 0 | D11: 0 | E11: 0 | F11: 0 | G11: 0 | H11: 0 | I11: 0 | J11: 0 | K11: 0 | L11: 0 | M11: 0 | N11: 0 | O11: 0
B12: 流动资产总额 | C12: =SUBTOTAL(109,流动资产[上一年度]) | D12: =SUBTOTAL(109,流动资产[1月]) | E12: =SUBTOTAL(109,流动资产[2月]) | F12: =SUBTOTAL(109,流动资产[3月]) | G12: =SUBTOTAL(109,流动资产[4月]) | H12: =SUBTOTAL(109,流动资产[5月]) | I12: =SUBTOTAL(109,流动资产[6月]) | J12: =SUBTOTAL(109,流动资产[7月]) | K12: =SUBTOTAL(109,流动资产[8月]) | L12: =SUBTOTAL(109,流动资产[9月]) | M12: =SUBTOTAL(109,流动资产[10月]) | N12: =SUBTOTAL(109,流动资产[11月]) | O12: =SUBTOTAL(109,流动资产[12月])
A14: 从右侧单元格开始，在“固定资产”表格中输入详细信息。下一条说明位于单元格 A21 中。 | B14: 固定资产： | C14: 上一年度 | D14: 1月 | E14: 2月 | F14: 3月 | G14: 4月 | H14: 5月 | I14: 6月 | J14: 7月 | K14: 8月 | L14: 9月 | M14: 10月 | N14: 11月 | O14: 12月
B15: 财产和设备 | C15: 0 | D15: 0 | E15: 0 | F15: 0 | G15: 0 | H15: 0 | I15: 0 | J15: 0 | K15: 0 | L15: 0 | M15: 0 | N15: 0 | O15: 0
B16: 租赁权益改良 | C16: 0 | D16: 0 | E16: 0 | F16: 0 | G16: 0 | H16: 0 | I16: 0 | J16: 0 | K16: 0 | L16: 0 | M16: 0 | N16: 0 | O16: 0
B17: 所有者权益及其他投资 | C17: 0 | D17: 0 | E17: 0 | F17: 0 | G17: 0 | H17: 0 | I17: 0 | J17: 0 | K17: 0 | L17: 0 | M17: 0 | N17: 0 | O17: 0
B18: 减去累计折旧 | C18: 0 | D18: 0 | E18: 0 | F18: 0 | G18: 0 | H18: 0 | I18: 0 | J18: 0 | K18: 0 | L18: 0 | M18: 0 | N18: 0 | O18: 0
B19: 固定资产总额 | C19: =SUBTOTAL(109,固定资产[上一年度]) | D19: =SUBTOTAL(109,固定资产[1月]) | E19: =SUBTOTAL(109,固定资产[2月]) | F19: =SUBTOTAL(109,固定资产[3月]) | G19: =SUBTOTAL(109,固定资产[4月]) | H19: =SUBTOTAL(109,固定资产[5月]) | I19: =SUBTOTAL(109,固定资产[6月]) | J19: =SUBTOTAL(109,固定资产[7月]) | K19: =SUBTOTAL(109,固定资产[8月]) | L19: =SUBTOTAL(109,固定资产[9月]) | M19: =SUBTOTAL(109,固定资产[10月]) | N19: =SUBTOTAL(109,固定资产[11月]) | O19: =SUBTOTAL(109,固定资产[12月])
A21: 从右侧单元格开始，在“其他资产”表格中输入详细信息。下一条说明位于单元格 A25 中。 | B21: 其他资产： | C21: 上一年度 | D21: 1月 | E21: 2月 | F21: 3月 | G21: 4月 | H21: 5月 | I21: 6月 | J21: 7月 | K21: 8月 | L21: 9月 | M21: 10月 | N21: 11月 | O21: 12月
B22: 商誉 | C22: 0 | D22: 0 | E22: 0 | F22: 0 | G22: 0 | H22: 0 | I22: 0 | J22: 0 | K22: 0 | L22: 0 | M22: 0 | N22: 0 | O22: 0
B23: 其他资产总额 | C23: =SUBTOTAL(109,其他资产[上一年度]) | D23: =SUBTOTAL(109,其他资产[1月]) | E23: =SUBTOTAL(109,其他资产[2月]) | F23: =SUBTOTAL(109,其他资产[3月]) | G23: =SUBTOTAL(109,其他资产[4月]) | H23: =SUBTOTAL(109,其他资产[5月]) | I23: =SUBTOTAL(109,其他资产[6月]) | J23: =SUBTOTAL(109,其他资产[7月]) | K23: =SUBTOTAL(109,其他资产[8月]) | L23: =SUBTOTAL(109,其他资产[9月]) | M23: =SUBTOTAL(109,其他资产[10月]) | N23: =SUBTOTAL(109,其他资产[11月]) | O23: =SUBTOTAL(109,其他资产[12月])
A25: 单元格 C25 中自动计算上一年度的资产总额，单元格 D25 中自动计算当前年度的资产总额。下一条说明位于单元格 A27 中。 | B25: 资产总额 | C25: =其他资产[[#Totals],[上一年度]]+固定资产[[#Totals],[上一年度]]+流动资产[[#Totals],[上一年度]] | D25: =其他资产[[#Totals],[1月]]+固定资产[[#Totals],[1月]]+流动资产[[#Totals],[1月]] | E25: =其他资产[[#Totals],[2月]]+固定资产[[#Totals],[2月]]+流动资产[[#Totals],[2月]] | F25: =其他资产[[#Totals],[3月]]+固定资产[[#Totals],[3月]]+流动资产[[#Totals],[3月]] | G25: =其他资产[[#Totals],[4月]]+固定资产[[#Totals],[4月]]+流动资产[[#Totals],[4月]] | H25: =其他资产[[#Totals],[5月]]+固定资产[[#Totals],[5月]]+流动资产[[#Totals],[5月]] | I25: =其他资产[[#Totals],[6月]]+固定资产[[#Totals],[6月]]+流动资产[[#Totals],[6月]] | J25: =其他资产[[#Totals],[7月]]+固定资产[[#Totals],[7月]]+流动资产[[#Totals],[7月]] | K25: =其他资产[[#Totals],[8月]]+固定资产[[#Totals],[8月]]+流动资产[[#Totals],[8月]] | L25: =其他资产[[#Totals],[9月]]+固定资产[[#Totals],[9月]]+流动资产[[#Totals],[9月]] | M25: =其他资产[[#Totals],[10月]]+固定资产[[#Totals],[10月]]+流动资产[[#Totals],[10月]] | N25: =其他资产[[#Totals],[11月]]+固定资产[[#Totals],[11月]]+流动资产[[#Totals],[11月]] | O25: =其他资产[[#Totals],[12月]]+固定资产[[#Totals],[12月]]+流动资产[[#Totals],[12月]]
A27: 负债和所有者权益标签位于右侧单元格中。 | B27: 负债和所有者权益
A28: 从右侧单元格开始，在“流动负债”表格中输入详细信息。下一条指示位于单元格 A37 中。 | B28: 流动负债： | C28: 上一年度 | D28: 1月 | E28: 2月 | F28: 3月 | G28: 4月 | H28: 5月 | I28: 6月 | J28: 7月 | K28: 8月 | L28: 9月 | M28: 10月 | N28: 11月 | O28: 12月
B29: 应付帐款 | C29: 0 | D29: 0 | E29: 0 | F29: 0 | G29: 0 | H29: 0 | I29: 0 | J29: 0 | K29: 0 | L29: 0 | M29: 0 | N29: 0 | O29: 0
B30: 应付工资 | C30: 0 | D30: 0 | E30: 0 | F30: 0 | G30: 0 | H30: 0 | I30: 0 | J30: 0 | K30: 0 | L30: 0 | M30: 0 | N30: 0 | O30: 0
B31: 应付薪酬 | C31: 0 | D31: 0 | E31: 0 | F31: 0 | G31: 0 | H31: 0 | I31: 0 | J31: 0 | K31: 0 | L31: 0 | M31: 0 | N31: 0 | O31: 0
B32: 应付所得税 | C32: 0 | D32: 0 | E32: 0 | F32: 0 | G32: 0 | H32: 0 | I32: 0 | J32: 0 | K32: 0 | L32: 0 | M32: 0 | N32: 0 | O32: 0
B33: 预收收入 | C33: 0 | D33: 0 | E33: 0 | F33: 0 | G33: 0 | H33: 0 | I33: 0 | J33: 0 | K33: 0 | L33: 0 | M33: 0 | N33: 0 | O33: 0
B34: 其他 | C34: 0 | D34: 0 | E34: 0 | F34: 0 | G34: 0 | H34: 0 | I34: 0 | J34: 0 | K34: 0 | L34: 0 | M34: 0 | N34: 0 | O34: 0
B35: 流动负债总额 | C35: =SUBTOTAL(109,流动负债[上一年度]) | D35: =SUBTOTAL(109,流动负债[1月]) | E35: =SUBTOTAL(109,流动负债[2月]) | F35: =SUBTOTAL(109,流动负债[3月]) | G35: =SUBTOTAL(109,流动负债[4月]) | H35: =SUBTOTAL(109,流动负债[5月]) | I35: =SUBTOTAL(109,流动负债[6月]) | J35: =SUBTOTAL(109,流动负债[7月]) | K35: =SUBTOTAL(109,流动负债[8月]) | L35: =SUBTOTAL(109,流动负债[9月]) | M35: =SUBTOTAL(109,流动负债[10月]) | N35: =SUBTOTAL(109,流动负债[11月]) | O35: =SUBTOTAL(109,流动负债[12月])
A37: 从右侧单元格开始，在“长期负债”表格中输入详细信息。下一条说明位于单元格 A41 中。 | B37: 长期负债： | C37: 上一年度 | D37: 1月 | E37: 2月 | F37: 3月 | G37: 4月 | H37: 5月 | I37: 6月 | J37: 7月 | K37: 8月 | L37: 9月 | M37: 10月 | N37: 11月 | O37: 12月
B38: 应付抵押款 | C38: 0 | D38: 0 | E38: 0 | F38: 0 | G38: 0 | H38: 0 | I38: 0 | J38: 0 | K38: 0 | L38: 0 | M38: 0 | N38: 0 | O38: 0
B39: 长期负债总额 | C39: =SUBTOTAL(109,长期负债[上一年度]) | D39: =SUBTOTAL(109,长期负债[1月]) | E39: =SUBTOTAL(109,长期负债[2月]) | F39: =SUBTOTAL(109,长期负债[3月]) | G39: =SUBTOTAL(109,长期负债[4月]) | H39: =SUBTOTAL(109,长期负债[5月]) | I39: =SUBTOTAL(109,长期负债[6月]) | J39: =SUBTOTAL(109,长期负债[7月]) | K39: =SUBTOTAL(109,长期负债[8月]) | L39: =SUBTOTAL(109,长期负债[9月]) | M39: =SUBTOTAL(109,长期负债[10月]) | N39: =SUBTOTAL(109,长期负债[11月]) | O39: =SUBTOTAL(109,长期负债[12月])
A41: 从右侧单元格开始，在“所有者权益”表格中输入详细信息。下一条指示位于单元格 A46 中。 | B41: 所有者权益： | C41: 上一年度 | D41: 1月 | E41: 2月 | F41: 3月 | G41: 4月 | H41: 5月 | I41: 6月 | J41: 7月 | K41: 8月 | L41: 9月 | M41: 10月 | N41: 11月 | O41: 12月
B42: 投资资本 | C42: 0 | D42: 0 | E42: 0 | F42: 0 | G42: 0 | H42: 0 | I42: 0 | J42: 0 | K42: 0 | L42: 0 | M42: 0 | N42: 0 | O42: 0
B43: 累计留存收益 | C43: 0 | D43: 0 | E43: 0 | F43: 0 | G43: 0 | H43: 0 | I43: 0 | J43: 0 | K43: 0 | L43: 0 | M43: 0 | N43: 0 | O43: 0
B44: 所有者权益总额 | C44: =SUBTOTAL(109,所有者权益[上一年度]) | D44: =SUBTOTAL(109,所有者权益[1月]) | E44: =SUBTOTAL(109,所有者权益[2月]) | F44: =SUBTOTAL(109,所有者权益[3月]) | G44: =SUBTOTAL(109,所有者权益[4月]) | H44: =SUBTOTAL(109,所有者权益[5月]) | I44: =SUBTOTAL(109,所有者权益[6月]) | J44: =SUBTOTAL(109,所有者权益[7月]) | K44: =SUBTOTAL(109,所有者权益[8月]) | L44: =SUBTOTAL(109,所有者权益[9月]) | M44: =SUBTOTAL(109,所有者权益[10月]) | N44: =SUBTOTAL(109,所有者权益[11月]) | O44: =SUBTOTAL(109,所有者权益[12月])
A46: 单元格 C46 中自动计算上一年度的负债和所有者权益总额，单元格 D46 中自动计算当前年度的负债和所有者权益总额。下一条指示位于单元格 A49 中。 | B46: 负债和所有者权益总额 | C46: =所有者权益[[#Totals],[上一年度]]+长期负债[[#Totals],[上一年度]]+流动负债[[#Totals],[上一年度]] | D46: =所有者权益[[#Totals],[1月]]+长期负债[[#Totals],[1月]]+流动负债[[#Totals],[1月]] | E46: =所有者权益[[#Totals],[2月]]+长期负债[[#Totals],[2月]]+流动负债[[#Totals],[2月]] | F46: =所有者权益[[#Totals],[3月]]+长期负债[[#Totals],[3月]]+流动负债[[#Totals],[3月]] | G46: =所有者权益[[#Totals],[4月]]+长期负债[[#Totals],[4月]]+流动负债[[#Totals],[4月]] | H46: =所有者权益[[#Totals],[5月]]+长期负债[[#Totals],[5月]]+流动负债[[#Totals],[5月]] | I46: =所有者权益[[#Totals],[6月]]+长期负债[[#Totals],[6月]]+流动负债[[#Totals],[6月]] | J46: =所有者权益[[#Totals],[7月]]+长期负债[[#Totals],[7月]]+流动负债[[#Totals],[7月]] | K46: =所有者权益[[#Totals],[8月]]+长期负债[[#Totals],[8月]]+流动负债[[#Totals],[8月]] | L46: =所有者权益[[#Totals],[9月]]+长期负债[[#Totals],[9月]]+流动负债[[#Totals],[9月]] | M46: =所有者权益[[#Totals],[10月]]+长期负债[[#Totals],[10月]]+流动负债[[#Totals],[10月]] | N46: =所有者权益[[#Totals],[11月]]+长期负债[[#Totals],[11月]]+流动负债[[#Totals],[11月]] | O46: =所有者权益[[#Totals],[12月]]+长期负债[[#Totals],[12月]]+流动负债[[#Totals],[12月]]
A49: 单元格 C49 中自动计算上一年度的余额，单元格 D49 中自动计算当前年度的余额。 | B49: 余额 | C49: =SUM(C25-C46) | D49: =SUM(D25-D46) | E49: =SUM(E25-E46) | F49: =SUM(F25-F46) | G49: =SUM(G25-G46) | H49: =SUM(H25-H46) | I49: =SUM(I25-I46) | J49: =SUM(J25-J46) | ... O49: =SUM(O25-O46)

Sheet 年同比图表

Sheet 总汇概览

Sheet 待确认
A1: 日期 | B1: 平台 | C1: 类型 | D1: 金额 | E1: 分类 | F1: 摘要 | G1: 来源文件 | H1: 置信度 | I1: 备注 | J1: 确认状态 | K1: 来源冲突 | L1: 记录ID | M1: 处理批次 | N1: 原始文本
A2: 2026-04-23 | B2: WeChat | C2: 支出 | D2: 700 | E2: 外部服务 | F2: 成都东恒国际大厦汇泊停车月卡 | G2: 账单截图/IMG_7828.PNG | H2: 高 | I2: 月卡停车费；已汇总入正式月度表 | J2: 已入账 | L2: 705c527aad57acd7 | M2: 2026-05-22-post-confirm | N2: 皇龙成都分公司 成都东恒国际大厦汇泊停车月卡_web 实付款700
A3: 2026-04-29 | B3: WeChat | C3: 成本 | D3: 44.6 | E3: 购买费用 | F3: 工作室衣杆衣架 | G3: 账单截图/IMG_7827.PNG | H3: 中 | I3: 工作室用品，是否计入成本待确认；已汇总入正式月度表 | J3: 已入账 | L3: ab2a3e036ea6cd5a | M3: 2026-05-22-post-confirm | N3: 转账-转给爱吃DQ的仓鼠 工作室衣杆衣架 -44.60
A4: 2026-05-02 | B4: WeChat | C4: 成本 | D4: 10000 | E4: 购买费用 | F4: 收购工作室服装、道具 | G4: 账单截图/IMG_7826.PNG | H4: 高 | I4: 已确认同正式流水：收购工作室服装、道具；已在收支财务报表入账 | J4: 已入账 | L4: cd1c8692dd960c1f | M4: 20260522-010436-218391 | N4: 转账-转给爱吃DQ的仓鼠 微信转账 -10000；已确认为收购工作室服装、道具
A5: 2026-04-18 | B5: Taobao | C5: 成本 | D5: 576 | E5: 购买费用 | F5: 华姿仪赏汉服老店 服饰订单 | G5: 账单截图/IMG_7833.PNG | H5: 中 | I5: 服饰用途待确认，若为拍摄或工作服可保留为成本；已汇总入正式月度表 | J5: 已入账 | L5: ae9e80fbe64fd8e1 | M5: 2026-05-22-post-confirm | N5: 华姿仪赏贵妃云裳唐风诃子裙亮片刺绣大袖衫汉服襦裙套装 合计576
A6: 2026-05-13 | B6: Taobao | C6: 成本 | D6: 404 | E6: 购买费用 | F6: 直播桌子主播用专用带货台式工作台 | G6: 账单截图/IMG_7831.PNG | H6: 高 | I6: 直播桌/工作台采购；已汇总入正式月度表 | J6: 已入账 | L6: 4829f87152d5d028 | M6: 2026-05-22-post-confirm | N6: 枝音佳家具旗舰店 直播桌子主播用专用带货台式工作台 实付款404
A7: 2026-05-16 | B7: WeChat | C7: 成本 | D7: 577.83 | E7: 购买费用 | F7: 工作室化妆品 | G7: 账单截图/IMG_7825.PNG | H7: 高 | I7: 微信转账，备注已写明工作室化妆品；已汇总入正式月度表 | J7: 已入账 | L7: 9307486a4a38daa5 | M7: 2026-05-22-post-confirm | N7: 转账-转给爱吃DQ的仓鼠 工作室化妆品 -577.83
A8: 2026-05-16 | B8: Taobao | C8: 成本 | D8: 825 | E8: 购买费用 | F8: 化妆镜直播专用镜子 3件 | G8: 账单截图/IMG_7829.PNG | H8: 高 | I8: 镜子/梳妆台采购；已汇总入正式月度表 | J8: 已入账 | L8: 40bfa81651a6b0f7 | M8: 2026-05-22-post-confirm | N8: 化妆镜直播专用镜子台式大号高清桌面方形卧室梳妆台镜镜子美妆镜 实付款825
A9: 2026-05-17 | B9: WeChat | C9: 成本 | D9: 860 | E9: 购买费用 | F9: 神牛 LR500 化妆室灯棒 | G9: 账单截图/IMG_7823.PNG | H9: 高 | I9: 已确认：购买化妆室灯棒 Godox LR500；已在收支财务报表第13行入账 | J9: 已入账 | L9: 7f9d8dccf36ab2be | M9: 20260522-010436-218391 | N9: 转账-转给Millenaire Lsp 微信转账 -860；已确认为购买化妆室灯棒 Godox LR500
A10: 2026-05-17 | B10: Alipay | C10: 支出 | D10: 366 | E10: 补给（办公室和运营） | F10: 滴滴加油 延长壳牌加油站（青羊苏坡） | G10: 账单截图/IMG_7830.PNG | H10: 中 | I10: 车辆加油，是否全部计入工作室运营待确认；已汇总入正式月度表 | J10: 已入账 | L10: 5bae6d6ab2755290 | M10: 2026-05-22-post-confirm | N10: 滴滴加油 延长壳牌加油站（青羊苏坡） 交易成功 -366
A11: 2026-05-17 | B11: Taobao | C11: 成本 | D11: 592.9 | E11: 购买费用 | F11: 惜物国风 汉服配饰与内搭订单 | G11: 账单截图/IMG_7835.PNG | H11: 中 | I11: 服装/配饰用途待确认，若用于拍摄或服务可计入成本；已汇总入正式月度表 | J11: 已入账 | L11: 85e971171ed8e8f1 | M11: 2026-05-22-post-confirm | N11: 惜物国风 汉服配饰配件、内搭里衣、抱腰等 合计592.9
A12: 2026-05-18 | B12: WeChat | C12: 成本 | D12: 696 | E12: 购买费用 | F12: 工作室化妆品 | G12: 账单截图/IMG_7824.PNG | H12: 高 | I12: 聊天截图注明工作室化妆品；已在收支财务报表第14行入账 | J12: 已入账 | L12: 7f55ee56fd468d8a | M12: 20260522-010436-218391 | N12: 聊天截图显示 696 元转账，并注明“工作室化妆品”
A13: 2026-05-19 | B13: WeChat | C13: 支出 | D13: 3 | E13: 外部服务 | F13: 厚都为民-缴费 | G13: 账单截图/IMG_7822.PNG | H13: 中 | I13: 小额缴费，疑似停车相关；已汇总入正式月度表 | J13: 已入账 | L13: 9d39b2e2d56ea509 | M13: 2026-05-22-post-confirm | N13: 厚都 厚都为民-缴费 -3
... A255: 2026-07-05 | B255: 微信 | C255: 收入 | D255: 0.58 | E255: 待分类 | F255: 揭金盖 “码”上赢1亿个现金红包 / / / 已到账 | G255: 账单导入/2026-07-05/extracted/微信/微信支付账单流水文件(20260405-20260705)——【解压密码可在微信支付公众号查看】.xlsx | H255: 中 | I255: 个人/公司归属不明确，请确认 | J255: 待确认 | L255: c7016e4e96c933d6 | M255: 20260705-174222-auto-bills | N255: 2026-07-05 14:07:39 | 其他 | 揭金盖 “码”上赢1亿个现金红包 | / | 收入 | 0.58 | / | 已到账 | 147296570226070510109004132298149821131221603 | 131020406048300269420752026070543460327262 | 揭金盖 “码”上赢1亿个现金红包
